Chào bạn,

Rất sẵn lòng giải thích chi tiết về phương thức `.catchError()` trong Dart và Flutter. Đây là một công cụ cực kỳ quan trọng để xử lý lỗi trong lập trình bất đồng bộ (asynchronous programming).

### 1. `Future` và Lập trình bất đồng bộ

Trước khi đi vào `.catchError()`, chúng ta cần hiểu về `Future`.

Trong Dart, một `Future` đại diện cho một giá trị hoặc một lỗi sẽ có sẵn trong tương lai. Hãy tưởng tượng bạn đang gọi một API để lấy dữ liệu. Quá trình này không diễn ra ngay lập tức; nó cần thời gian. `Future` chính là "lời hứa" rằng bạn sẽ nhận được kết quả (dữ liệu) hoặc một lỗi (ví dụ: mất kết nối mạng) sau một khoảng thời gian.

Một `Future` có thể hoàn thành theo hai cách:
1.  **Thành công (Completed with a value):** Trả về dữ liệu bạn mong đợi.
2.  **Thất bại (Completed with an error):** Ném ra một lỗi (Exception/Error).

`.catchError()` chính là cơ chế để bạn "bắt" và xử lý khi `Future` hoàn thành theo cách thứ hai.

### 2. `.catchError()` là gì?

`.catchError()` là một phương thức được định nghĩa trên đối tượng `Future`. Nó cho phép bạn đăng ký một hàm callback sẽ được thực thi **chỉ khi** `Future` đó hoặc bất kỳ `Future` nào trước nó trong chuỗi (chain) thất bại.

**Cú pháp cơ bản:**

```dart
future
    .then((value) {
      // Xử lý khi Future thành công
    })
    .catchError((error, stackTrace) {
      // Xử lý khi Future thất bại
      // 'error' là đối tượng lỗi (ví dụ: Exception)
      // 'stackTrace' là dấu vết của lỗi, rất hữu ích để debug
    });
```

### 3. Cách `.catchError()` hoạt động và các trường hợp sử dụng

Hãy xem qua các ví dụ từ đơn giản đến phức tạp.

#### Ví dụ 1: Xử lý lỗi cơ bản

Giả sử chúng ta có một hàm giả lập việc lấy dữ liệu người dùng, và nó có thể thất bại.

```dart
Future<String> fetchUserData() {
  // Giả lập một lỗi xảy ra sau 2 giây
  return Future.delayed(const Duration(seconds: 2), () {
    throw Exception('Không thể tải dữ liệu người dùng!');
  });
}

void main() {
  print('Bắt đầu lấy dữ liệu...');
  
  fetchUserData()
    .then((userData) {
      // Khối .then() này sẽ KHÔNG BAO GIỜ được gọi vì Future bị lỗi
      print('Dữ liệu nhận được: $userData');
    })
    .catchError((err) {
      // Khi Future ném ra Exception, khối .catchError() này sẽ được thực thi
      print('Đã xảy ra lỗi: $err');
    });
    
  print('Yêu cầu đã được gửi đi (mã nguồn tiếp tục chạy)...');
}
```

**Kết quả output:**
```
Bắt đầu lấy dữ liệu...
Yêu cầu đã được gửi đi (mã nguồn tiếp tục chạy)...
(đợi 2 giây)
Đã xảy ra lỗi: Exception: Không thể tải dữ liệu người dùng!
```

#### Ví dụ 2: "Phục hồi" từ lỗi (Recovering from an error)

Một trong những tính năng mạnh mẽ nhất của `.catchError()` là nó cho phép bạn cung cấp một **giá trị thay thế** khi có lỗi xảy ra. Điều này giúp chuỗi `Future` tiếp tục chạy một cách bình thường thay vì dừng lại.

```dart
Future<String> fetchUsername() {
  return Future.delayed(const Duration(seconds: 1), () {
    throw Exception('API không phản hồi');
  });
}

void main() {
  fetchUsername()
    .then((username) => 'Tên người dùng: $username')
    .catchError((err) {
      // Lỗi đã xảy ra!
      print('Lỗi khi lấy tên người dùng: $err');
      // Thay vì để lỗi lan truyền, chúng ta "phục hồi" bằng cách trả về một giá trị mặc định.
      // Giá trị này phải có cùng kiểu dữ liệu với Future (String).
      return 'Khách'; 
    })
    .then((finalResult) {
      // Vì .catchError() đã trả về một giá trị, khối .then() này sẽ được thực thi.
      print('Xin chào, $finalResult!');
    });
}
```

**Kết quả output:**
```
Lỗi khi lấy tên người dùng: Exception: API không phản hồi
Xin chào, Khách!
```
Ở đây, `.catchError()` đã biến một `Future` thất bại thành một `Future` thành công với giá trị là `'Khách'`, cho phép khối `.then()` tiếp theo được thực thi.

#### Ví dụ 3: Sử dụng trong Flutter UI

Đây là kịch bản phổ biến nhất. Bạn muốn gọi API, hiển thị `CircularProgressIndicator` khi đang tải, hiển thị dữ liệu nếu thành công, và hiển thị thông báo lỗi nếu thất bại.

```dart
import 'package:flutter/material.dart';

class UserProfileScreen extends StatefulWidget {
  const UserProfileScreen({super.key});

  @override
  State<UserProfileScreen> createState() => _UserProfileScreenState();
}

class _UserProfileScreenState extends State<UserProfileScreen> {
  String _userData = 'Đang tải...';
  bool _isLoading = true;

  @override
  void initState() {
    super.initState();
    _loadUserData();
  }

  Future<void> _loadUserData() {
    // Giả lập gọi API có thể thất bại
    return Future.delayed(const Duration(seconds: 3), () {
      throw Exception('Không có kết nối mạng');
    })
    .then((data) {
      setState(() {
        _userData = data; // Dữ liệu thành công
        _isLoading = false;
      });
    })
    .catchError((error) {
      // Xử lý lỗi ở đây!
      setState(() {
        _userData = 'Không thể tải dữ liệu. Vui lòng thử lại.'; // Thông báo lỗi cho người dùng
        _isLoading = false;
      });
      // Hiển thị SnackBar để thông báo lỗi
      ScaffoldMessenger.of(context).showSnackBar(
        SnackBar(content: Text('Lỗi: $error')),
      );
    });
  }

  @override
  Widget build(BuildContext context) {
    return Scaffold(
      appBar: AppBar(title: const Text('Hồ sơ người dùng')),
      body: Center(
        child: _isLoading
            ? const CircularProgressIndicator()
            : Text(_userData, style: const TextStyle(fontSize: 18)),
      ),
    );
  }
}
```

Trong ví dụ này, `.catchError()` đóng vai trò quan trọng trong việc cập nhật UI để phản ánh trạng thái lỗi, giúp người dùng hiểu được chuyện gì đang xảy ra.

### 4. So sánh `.catchError()` và `try-catch` với `async/await`

Bạn cũng có thể xử lý lỗi trong code bất đồng bộ bằng cách sử dụng `async/await` kết hợp với `try-catch`. Đây là một cách tiếp cận khác và thường dễ đọc hơn.

**Sử dụng `.catchError()`:**
```dart
void loadDataWithCatchError() {
  fetchData()
    .then((result) => print(result))
    .catchError((err) => print('Lỗi: $err'));
}
```

**Sử dụng `try-catch` với `async/await`:**
```dart
Future<void> loadDataWithTryCatch() async {
  try {
    final result = await fetchData(); // 'await' sẽ tạm dừng hàm cho đến khi Future hoàn thành
    print(result);
  } catch (err) {
    // Nếu Future thất bại, 'await' sẽ ném ra lỗi và khối 'catch' sẽ bắt được nó.
    print('Lỗi: $err');
  }
}
```

**Khi nào dùng cái nào?**

*   **Dùng `async/await` với `try-catch`:**
    *   Khi bạn có nhiều bước bất đồng bộ phụ thuộc lẫn nhau. Code sẽ trông giống như code đồng bộ, rất dễ đọc và bảo trì.
    *   Đây là cách tiếp cận hiện đại và được khuyến khích trong hầu hết các trường hợp.

*   **Dùng `.then().catchError()`:**
    *   Khi bạn có một chuỗi xử lý đơn giản và muốn theo phong cách lập trình hàm (functional programming).
    *   Khi bạn đang làm việc với các API cũ hơn không sử dụng `async/await`.
    *   Khi bạn muốn "phục hồi" từ lỗi một cách rõ ràng như trong Ví dụ 2.

### Tóm tắt

*   `.catchError()` là một phương thức của `Future` dùng để xử lý các lỗi xảy ra trong quá trình thực thi bất đồng bộ.
*   Nó nhận vào một hàm callback với tham số là `error` và (tùy chọn) `stackTrace`.
*   Bạn có thể dùng nó để ghi log lỗi, cập nhật UI để hiển thị thông báo, hoặc "phục hồi" bằng cách trả về một giá trị mặc định.
*   Đây là một công cụ thiết yếu để xây dựng các ứng dụng Flutter mạnh mẽ và thân thiện với người dùng, có khả năng xử lý các tình huống không mong muốn như lỗi mạng hoặc lỗi API.
